<?xml version="1.0" ?>
<sdf version="1.5">
  <model name="HEAD">
    <link name="FACE">
      <pose>1.5371 -1.50745 0.5 0 -0 0</pose>
      <inertial>
        <mass>0.47386924</mass>
        <inertia>
          <ixx>0.00458492</ixx>
          <iyy>0.00475384</iyy>
          <izz>0.00222689</izz>
          <ixy>0</ixy>
          <ixz>0</ixz>
          <iyz>0.00007495</iyz>
        </inertia>
      </inertial>
      <link name='defaultModel_0::custom_-27'>
      <pose>0 0 0 0 -0 0</pose>
      <gravity>1</gravity>
      <self_collide>0</self_collide>
      <kinematic>0</kinematic>
      <collision name="collision">
        <geometry>
          <box>
            <size>0.17 0.15 0.16</size>
          </box>
          <mesh>
            <uri>/media/trannguyenphuongtrinh_eeit13/01D0512D26AB19B0/ROBOT/retry2/face/Face.STL</uri>
            <scale>0.01 0.01 0.01</scale>
          </mesh>
        </geometry>
        <pose>0 0 0 0 -0 0</pose>
      </collision>
      <collision name="EARcap_right">
        <pose>6.43341 25 0.5 0 -0 0</pose>
        <geometry>
          <mesh>
            <uri>/media/trannguyenphuongtrinh_eeit13/01D0512D26AB19B0/ROBOT/retry2/ear/ear_cap.STL</uri>
            <scale>0.01 0.01 0.01</scale>
          </mesh>
        </geometry>
        <surface>
          <friction>
            <ode>
              <mu>0</mu>
              <mu2>0</mu2>
              <slip1>1.0</slip1>
              <slip2>1.0</slip2>
            </ode>
          </friction>
        </surface>
      </collision>
       <collision name="EARcap_left">
        <pose>0 0 0 0 -0 0</pose>
        <geometry>
          <mesh>
            <uri>/media/trannguyenphuongtrinh_eeit13/01D0512D26AB19B0/ROBOT/retry2/ear/ear_cap.STL</uri>
            <scale>0.01 0.01 0.01</scale>
          </mesh>
        </geometry>
        <surface>
          <friction>
            <ode>
              <mu>0</mu>
              <mu2>0</mu2>
              <slip1>1.0</slip1>
              <slip2>1.0</slip2>
            </ode>
          </friction>
        </surface>
      </collision>
      <visual name='custom_-27_visual'>
        <pose>0 0 0 0 -0 0</pose>
        <geometry>
          <mesh>
            <uri>/media/trannguyenphuongtrinh_eeit13/01D0512D26AB19B0/ROBOT/retry2/face/Face.STL</uri>
            <scale>0.01 0.01 0.01</scale>
          </mesh>
        </geometry>
        <material>
          <script>
            <uri>file://media/materials/scripts/gazebo.material</uri>
            <name>Gazebo/Grey</name>
          </script>
        </material>
      </visual>
      <visual name="EARcap_right">
        <pose>-0.200 0 -0.12 0 0 0</pose>
        <geometry>
          <mesh>
            <uri>/media/trannguyenphuongtrinh_eeit13/01D0512D26AB19B0/ROBOT/retry2/ear/ear_cap.STL</uri>
            <scale>0.01 0.01 0.01</scale>
          </mesh>
        </geometry>
        <material>
          <script>
            <uri>file://media/materials/scripts/gazebo.material</uri>
            <name>Gazebo/FlatBlack</name>
          </script>
        </material>
      </visual>
      <visual name="EARcap_left">
        <pose>0 0 0 0 -0 0</pose>
        <geometry>
          <mesh>
            <uri>/media/trannguyenphuongtrinh_eeit13/01D0512D26AB19B0/ROBOT/retry2/ear/ear_cap.STL</uri>
            <scale>0.01 0.01 0.01</scale>
          </mesh>
        </geometry>
        <material>
          <script>
            <uri>file://media/materials/scripts/gazebo.material</uri>
            <name>Gazebo/FlatBlack</name>
          </script>
        </material>
      </visual>
    </link>
    <static>1</static>
    <allow_auto_disable>1</allow_auto_disable>
    <link name="RIGHT_eyebrown">
      <pose>0.1 -.17 0.11 0 1.5707 1.5707</pose>
      <inertial>
        <mass>0.00141734</mass>
        <inertia>
          <ixx>0.00000549</ixx>
          <iyy>0.00000025</iyy>
          <izz>0.00000564</izz>
          <ixy>-0.00000002</ixy>
          <ixz>0</ixz>
          <iyz>0.00000044</iyz>
        </inertia>
      </inertial>
      <collision name="collision">
        <geometry>
          <cylinder>
            <radius>0.11</radius>
            <length>0.05</length>
          </cylinder>
        </geometry>
        <surface>
          <friction>
            <ode>
              <mu>100000.0</mu>
              <mu2>100000.0</mu2>
              <slip1>0.0</slip1>
              <slip2>0.0</slip2>
            </ode>
          </friction>
        </surface>
      </collision>
      <visual name="visual">
        <geometry>
          <cylinder>
            <radius>0.11</radius>
            <length>0.05</length>
          </cylinder>
        </geometry>
        <material>
          <script>
            <uri>file://media/materials/scripts/gazebo.material</uri>
            <name>Gazebo/FlatBlack</name>
          </script>
        </material>
      </visual>
    </link>
    <link name="LEFT_eyebrown">
      <pose>0.1 .17 0.11 0 1.5707 1.5707</pose>
      <inertial>
        <mass>0.00141734</mass>
        <inertia>
          <ixx>0.00000549</ixx>
          <iyy>0.00000021</iyy>
          <izz>0.00000021</izz>
          <ixy>0.00000002</ixy>
          <ixz>0</ixz>
          <iyz>0.00000044</iyz>
        </inertia>
      </inertial>
      <collision name="collision">
        <geometry>
          <cylinder>
            <radius>0.11</radius>
            <length>0.05</length>
          </cylinder>
        </geometry>
        <surface>
          <friction>
            <ode>
              <mu>100000.0</mu>
              <mu2>100000.0</mu2>
              <slip1>0.0</slip1>
              <slip2>0.0</slip2>
            </ode>
          </friction>
        </surface>
      </collision>
      <visual name="visual">
        <geometry>
          <cylinder>
            <radius>0.11</radius>
            <length>0.05</length>
          </cylinder>
        </geometry>
        <material>
          <script>
            <uri>file://media/materials/scripts/gazebo.material</uri>
            <name>Gazebo/FlatBlack</name>
          </script>
        </material>
      </visual>
    </link>
    <link name="MOUTH">
      <pose>0 0 0.16 0 0 0</pose>
      <inertial>
        <mass>0.01601413</mass>
        <inertia>
          <ixx>0.00000755</ixx>
          <iyy>0.00003191</iyy>
          <izz>0.00003639</izz>
          <ixy>-0.00001262</ixy>
          <ixz>0</ixz>
          <iyz>0</iyz>
        </inertia>
      </inertial>
      <collision name="collision">
        <geometry>
          <box>
            <size>0.03 0.04 0.035</size>
          </box>
        </geometry>
      </collision>
      <collision name="castor_collision">
        <pose>-0.200 0 -0.12 0 0 0</pose>
        <geometry>
          <sphere>
            <radius>0.04</radius>
          </sphere>
        </geometry>
        <surface>
          <friction>
            <ode>
              <mu>0</mu>
              <mu2>0</mu2>
              <slip1>1.0</slip1>
              <slip2>1.0</slip2>
            </ode>
          </friction>
        </surface>
      </collision>
      <visual name="visual">
        <pose>0 0 0.04 0 0 0</pose>
        <geometry>
          <mesh>
            <uri>model://pioneer2dx/meshes/chassis.dae</uri>
          </mesh>
        </geometry>
      </visual>
      <visual name="castor_visual">
        <pose>-0.200 0 -0.12 0 0 0</pose>
        <geometry>
          <sphere>
            <radius>0.04</radius>
          </sphere>
        </geometry>
        <material>
          <script>
            <uri>file://media/materials/scripts/gazebo.material</uri>
            <name>Gazebo/FlatBlack</name>
          </script>
        </material>
      </visual>
    </link>
    <link name="MOUTH_movement">
      <pose>0.1 .17 0.11 0 1.5707 1.5707</pose>
      <inertial>
        <mass>0.00050854</mass>
        <inertia>
          <ixx>0</ixx>
          <iyy>0.00000001</iyy>
          <izz>0.00000002</izz>
          <ixy>0</ixy>
          <ixz>0</ixz>
          <iyz>0</iyz>
        </inertia>
      </inertial>
      <collision name="collision">
        <geometry>
          <cylinder>
            <radius>0.11</radius>
            <length>0.05</length>
          </cylinder>
        </geometry>
        <surface>
          <friction>
            <ode>
              <mu>100000.0</mu>
              <mu2>100000.0</mu2>
              <slip1>0.0</slip1>
              <slip2>0.0</slip2>
            </ode>
          </friction>
        </surface>
      </collision>
      <visual name="visual">
        <geometry>
          <cylinder>
            <radius>0.11</radius>
            <length>0.05</length>
          </cylinder>
        </geometry>
        <material>
          <script>
            <uri>file://media/materials/scripts/gazebo.material</uri>
            <name>Gazebo/FlatBlack</name>
          </script>
        </material>
      </visual>
    </link>
    <link name="MOUTH_cap">
      <pose>0.1 .17 0.11 0 1.5707 1.5707</pose>
      <inertial>
        <mass>0.00065494</mass>
        <inertia>
          <ixx>0</ixx>
          <iyy>0.00000008</iyy>
          <izz>0.00000007</izz>
          <ixy>0</ixy>
          <ixz>0</ixz>
          <iyz>0</iyz>
        </inertia>
      </inertial>
      <collision name="collision">
        <geometry>
          <cylinder>
            <radius>0.11</radius>
            <length>0.05</length>
          </cylinder>
        </geometry>
        <surface>
          <friction>
            <ode>
              <mu>100000.0</mu>
              <mu2>100000.0</mu2>
              <slip1>0.0</slip1>
              <slip2>0.0</slip2>
            </ode>
          </friction>
        </surface>
      </collision>
      <visual name="visual">
        <geometry>
          <cylinder>
            <radius>0.11</radius>
            <length>0.05</length>
          </cylinder>
        </geometry>
        <material>
          <script>
            <uri>file://media/materials/scripts/gazebo.material</uri>
            <name>Gazebo/FlatBlack</name>
          </script>
        </material>
      </visual>
    </link>
    <joint type="revolute" name="left_wheel_hinge">
      <pose>0 0 -0.03 0 0 0</pose>
      <child>left_wheel</child>
      <parent>chassis</parent>
      <axis>
        <xyz>0 1 0</xyz>
        <use_parent_model_frame>true</use_parent_model_frame>
      </axis>
    </joint>
    <joint type="revolute" name="right_wheel_hinge">
      <pose>0 0 0.03 0 0 0</pose>
      <child>right_wheel</child>
      <parent>chassis</parent>
      <axis>
        <xyz>0 1 0</xyz>
        <use_parent_model_frame>true</use_parent_model_frame>
      </axis>
    </joint>
    <plugin filename="libDiffDrivePlugin.so" name="diff_drive">
      <left_joint>left_wheel_hinge</left_joint>
      <right_joint>right_wheel_hinge</right_joint>
      <torque>5</torque>
    </plugin>
  </model>
</sdf>
